[2024-11-12T11:22:20.857+0000] {local_task_job_runner.py:120} INFO - ::group::Pre task execution logs
[2024-11-12T11:22:22.207+0000] {taskinstance.py:2076} INFO - Dependencies all met for dep_context=non-requeueable deps ti=<TaskInstance: Loan_Request_Report.Extract manual__2024-11-11T13:12:32.233093+00:00 [queued]>
[2024-11-12T11:22:22.227+0000] {taskinstance.py:2076} INFO - Dependencies all met for dep_context=requeueable deps ti=<TaskInstance: Loan_Request_Report.Extract manual__2024-11-11T13:12:32.233093+00:00 [queued]>
[2024-11-12T11:22:22.227+0000] {taskinstance.py:2306} INFO - Starting attempt 1 of 1
[2024-11-12T11:22:22.897+0000] {taskinstance.py:2330} INFO - Executing <Task(PythonOperator): Extract> on 2024-11-11 13:12:32.233093+00:00
[2024-11-12T11:22:24.444+0000] {standard_task_runner.py:90} INFO - Running: ['***', 'tasks', 'run', 'Loan_Request_Report', 'Extract', 'manual__2024-11-11T13:12:32.233093+00:00', '--job-id', '283', '--raw', '--subdir', 'DAGS_FOLDER/dagLoanRequest.py', '--cfg-path', '/tmp/tmprsvtsgyu']
[2024-11-12T11:22:24.449+0000] {standard_task_runner.py:91} INFO - Job 283: Subtask Extract
[2024-11-12T11:22:24.510+0000] {warnings.py:112} WARNING - /home/***/.local/lib/python3.12/site-packages/***/task/task_runner/standard_task_runner.py:62: DeprecationWarning: This process (pid=56) is multi-threaded, use of fork() may lead to deadlocks in the child.
  pid = os.fork()

[2024-11-12T11:22:24.520+0000] {standard_task_runner.py:64} INFO - Started process 65 to run task
[2024-11-12T11:22:24.660+0000] {task_command.py:426} INFO - Running <TaskInstance: Loan_Request_Report.Extract manual__2024-11-11T13:12:32.233093+00:00 [running]> on host 2bac939b7bc7
[2024-11-12T11:22:25.024+0000] {taskinstance.py:2648} INFO - Exporting env vars: AIRFLOW_CTX_DAG_OWNER='***' AIRFLOW_CTX_DAG_ID='Loan_Request_Report' AIRFLOW_CTX_TASK_ID='Extract' AIRFLOW_CTX_EXECUTION_DATE='2024-11-11T13:12:32.233093+00:00' AIRFLOW_CTX_TRY_NUMBER='1' AIRFLOW_CTX_DAG_RUN_ID='manual__2024-11-11T13:12:32.233093+00:00'
[2024-11-12T11:22:25.030+0000] {taskinstance.py:430} INFO - ::endgroup::
[2024-11-12T11:22:27.955+0000] {TSocket.py:133} ERROR - failed to resolve sockaddr for hive-server:10000
Traceback (most recent call last):
  File "/home/airflow/.local/lib/python3.12/site-packages/thrift/transport/TSocket.py", line 130, in open
    addrs = self._resolveAddr()
            ^^^^^^^^^^^^^^^^^^^
  File "/home/airflow/.local/lib/python3.12/site-packages/thrift/transport/TSocket.py", line 37, in _resolveAddr
    return socket.getaddrinfo(self.host,
           ^^^^^^^^^^^^^^^^^^^^^^^^^^^^^
  File "/usr/local/lib/python3.12/socket.py", line 964, in getaddrinfo
    for res in _socket.getaddrinfo(host, port, family, type, proto, flags):
               ^^^^^^^^^^^^^^^^^^^^^^^^^^^^^^^^^^^^^^^^^^^^^^^^^^^^^^^^^^^
socket.gaierror: [Errno -3] Temporary failure in name resolution
[2024-11-12T11:22:27.982+0000] {taskinstance.py:441} INFO - ::group::Post task execution logs
[2024-11-12T11:22:27.983+0000] {taskinstance.py:2905} ERROR - Task failed with exception
Traceback (most recent call last):
  File "/home/airflow/.local/lib/python3.12/site-packages/thrift/transport/TSocket.py", line 130, in open
    addrs = self._resolveAddr()
            ^^^^^^^^^^^^^^^^^^^
  File "/home/airflow/.local/lib/python3.12/site-packages/thrift/transport/TSocket.py", line 37, in _resolveAddr
    return socket.getaddrinfo(self.host,
           ^^^^^^^^^^^^^^^^^^^^^^^^^^^^^
  File "/usr/local/lib/python3.12/socket.py", line 964, in getaddrinfo
    for res in _socket.getaddrinfo(host, port, family, type, proto, flags):
               ^^^^^^^^^^^^^^^^^^^^^^^^^^^^^^^^^^^^^^^^^^^^^^^^^^^^^^^^^^^
socket.gaierror: [Errno -3] Temporary failure in name resolution

During handling of the above exception, another exception occurred:

Traceback (most recent call last):
  File "/home/airflow/.local/lib/python3.12/site-packages/airflow/models/taskinstance.py", line 465, in _execute_task
    result = _execute_callable(context=context, **execute_callable_kwargs)
             ^^^^^^^^^^^^^^^^^^^^^^^^^^^^^^^^^^^^^^^^^^^^^^^^^^^^^^^^^^^^^
  File "/home/airflow/.local/lib/python3.12/site-packages/airflow/models/taskinstance.py", line 432, in _execute_callable
    return execute_callable(context=context, **execute_callable_kwargs)
           ^^^^^^^^^^^^^^^^^^^^^^^^^^^^^^^^^^^^^^^^^^^^^^^^^^^^^^^^^^^^
  File "/home/airflow/.local/lib/python3.12/site-packages/airflow/models/baseoperator.py", line 401, in wrapper
    return func(self, *args, **kwargs)
           ^^^^^^^^^^^^^^^^^^^^^^^^^^^
  File "/home/airflow/.local/lib/python3.12/site-packages/airflow/operators/python.py", line 235, in execute
    return_value = self.execute_callable()
                   ^^^^^^^^^^^^^^^^^^^^^^^
  File "/home/airflow/.local/lib/python3.12/site-packages/airflow/operators/python.py", line 252, in execute_callable
    return self.python_callable(*self.op_args, **self.op_kwargs)
           ^^^^^^^^^^^^^^^^^^^^^^^^^^^^^^^^^^^^^^^^^^^^^^^^^^^^^
  File "/opt/airflow/dags/dagLoanRequest.py", line 36, in extract_task
    merged_df, original_df = extract_data_from_hive(kwargs['required_date'])
                             ^^^^^^^^^^^^^^^^^^^^^^^^^^^^^^^^^^^^^^^^^^^^^^^
  File "/opt/airflow/dags/etlProcess.py", line 98, in extract_data_from_hive
    conn = hive.Connection(host="hive-server", port=10000, database='m2t')
           ^^^^^^^^^^^^^^^^^^^^^^^^^^^^^^^^^^^^^^^^^^^^^^^^^^^^^^^^^^^^^^^
  File "/home/airflow/.local/lib/python3.12/site-packages/pyhive/hive.py", line 269, in __init__
    self._transport.open()
  File "/home/airflow/.local/lib/python3.12/site-packages/thrift_sasl/__init__.py", line 74, in open
    self._trans.open()
  File "/home/airflow/.local/lib/python3.12/site-packages/thrift/transport/TSocket.py", line 134, in open
    raise TTransportException(type=TTransportException.NOT_OPEN, message=msg, inner=gai)
thrift.transport.TTransport.TTransportException: failed to resolve sockaddr for hive-server:10000
[2024-11-12T11:22:28.090+0000] {taskinstance.py:1206} INFO - Marking task as FAILED. dag_id=Loan_Request_Report, task_id=Extract, run_id=manual__2024-11-11T13:12:32.233093+00:00, execution_date=20241111T131232, start_date=20241112T112222, end_date=20241112T112228
[2024-11-12T11:22:28.137+0000] {standard_task_runner.py:110} ERROR - Failed to execute job 283 for task Extract (failed to resolve sockaddr for hive-server:10000; 65)
[2024-11-12T11:22:28.186+0000] {local_task_job_runner.py:243} INFO - Task exited with return code 1
[2024-11-12T11:22:28.421+0000] {taskinstance.py:3503} INFO - 0 downstream tasks scheduled from follow-on schedule check
[2024-11-12T11:22:28.466+0000] {local_task_job_runner.py:222} INFO - ::endgroup::
