[2024-11-04T09:18:48.831+0000] {local_task_job_runner.py:120} INFO - ::group::Pre task execution logs
[2024-11-04T09:18:50.727+0000] {taskinstance.py:2076} INFO - Dependencies all met for dep_context=non-requeueable deps ti=<TaskInstance: Loan_Request_Report.Extract manual__2024-11-04T09:17:37.069884+00:00 [queued]>
[2024-11-04T09:18:51.815+0000] {taskinstance.py:2076} INFO - Dependencies all met for dep_context=requeueable deps ti=<TaskInstance: Loan_Request_Report.Extract manual__2024-11-04T09:17:37.069884+00:00 [queued]>
[2024-11-04T09:18:53.192+0000] {taskinstance.py:2306} INFO - Starting attempt 1 of 1
[2024-11-04T09:18:56.263+0000] {taskinstance.py:2330} INFO - Executing <Task(PythonOperator): Extract> on 2024-11-04 09:17:37.069884+00:00
[2024-11-04T09:18:59.638+0000] {warnings.py:112} WARNING - /home/***/.local/lib/python3.12/site-packages/***/task/task_runner/standard_task_runner.py:62: DeprecationWarning: This process (pid=213) is multi-threaded, use of fork() may lead to deadlocks in the child.
  pid = os.fork()

[2024-11-04T09:18:59.962+0000] {standard_task_runner.py:64} INFO - Started process 223 to run task
[2024-11-04T09:18:59.327+0000] {standard_task_runner.py:90} INFO - Running: ['***', 'tasks', 'run', 'Loan_Request_Report', 'Extract', 'manual__2024-11-04T09:17:37.069884+00:00', '--job-id', '24', '--raw', '--subdir', 'DAGS_FOLDER/dagLoanRequest.py', '--cfg-path', '/tmp/tmpbb_5_uum']
[2024-11-04T09:19:00.028+0000] {standard_task_runner.py:91} INFO - Job 24: Subtask Extract
[2024-11-04T09:19:07.166+0000] {task_command.py:426} INFO - Running <TaskInstance: Loan_Request_Report.Extract manual__2024-11-04T09:17:37.069884+00:00 [running]> on host f4ed2a87aeca
[2024-11-04T09:19:12.024+0000] {taskinstance.py:2648} INFO - Exporting env vars: AIRFLOW_CTX_DAG_OWNER='***' AIRFLOW_CTX_DAG_ID='Loan_Request_Report' AIRFLOW_CTX_TASK_ID='Extract' AIRFLOW_CTX_EXECUTION_DATE='2024-11-04T09:17:37.069884+00:00' AIRFLOW_CTX_TRY_NUMBER='1' AIRFLOW_CTX_DAG_RUN_ID='manual__2024-11-04T09:17:37.069884+00:00'
[2024-11-04T09:19:12.076+0000] {taskinstance.py:430} INFO - ::endgroup::
[2024-11-04T09:19:12.152+0000] {TSocket.py:149} INFO - Could not connect to ('127.0.0.1', 10000)
Traceback (most recent call last):
  File "/home/airflow/.local/lib/python3.12/site-packages/thrift/transport/TSocket.py", line 144, in open
    handle.connect(sockaddr)
ConnectionRefusedError: [Errno 111] Connection refused
[2024-11-04T09:19:12.184+0000] {TSocket.py:149} INFO - Could not connect to ('::1', 10000, 0, 0)
Traceback (most recent call last):
  File "/home/airflow/.local/lib/python3.12/site-packages/thrift/transport/TSocket.py", line 144, in open
    handle.connect(sockaddr)
OSError: [Errno 99] Cannot assign requested address
[2024-11-04T09:19:12.190+0000] {TSocket.py:152} ERROR - Could not connect to any of [('127.0.0.1', 10000), ('::1', 10000, 0, 0)]
[2024-11-04T09:19:12.191+0000] {taskinstance.py:441} INFO - ::group::Post task execution logs
[2024-11-04T09:19:12.197+0000] {taskinstance.py:2905} ERROR - Task failed with exception
Traceback (most recent call last):
  File "/home/airflow/.local/lib/python3.12/site-packages/airflow/models/taskinstance.py", line 465, in _execute_task
    result = _execute_callable(context=context, **execute_callable_kwargs)
             ^^^^^^^^^^^^^^^^^^^^^^^^^^^^^^^^^^^^^^^^^^^^^^^^^^^^^^^^^^^^^
  File "/home/airflow/.local/lib/python3.12/site-packages/airflow/models/taskinstance.py", line 432, in _execute_callable
    return execute_callable(context=context, **execute_callable_kwargs)
           ^^^^^^^^^^^^^^^^^^^^^^^^^^^^^^^^^^^^^^^^^^^^^^^^^^^^^^^^^^^^
  File "/home/airflow/.local/lib/python3.12/site-packages/airflow/models/baseoperator.py", line 401, in wrapper
    return func(self, *args, **kwargs)
           ^^^^^^^^^^^^^^^^^^^^^^^^^^^
  File "/home/airflow/.local/lib/python3.12/site-packages/airflow/operators/python.py", line 235, in execute
    return_value = self.execute_callable()
                   ^^^^^^^^^^^^^^^^^^^^^^^
  File "/home/airflow/.local/lib/python3.12/site-packages/airflow/operators/python.py", line 252, in execute_callable
    return self.python_callable(*self.op_args, **self.op_kwargs)
           ^^^^^^^^^^^^^^^^^^^^^^^^^^^^^^^^^^^^^^^^^^^^^^^^^^^^^
  File "/opt/airflow/dags/dagLoanRequest.py", line 31, in extract_task
    merged_df, original_df = extract_data_from_hive(kwargs['required_date'])
                             ^^^^^^^^^^^^^^^^^^^^^^^^^^^^^^^^^^^^^^^^^^^^^^^
  File "/opt/airflow/dags/etlProcess.py", line 84, in extract_data_from_hive
    conn = hive.Connection(host="localhost", port=10000, database='m2t')
           ^^^^^^^^^^^^^^^^^^^^^^^^^^^^^^^^^^^^^^^^^^^^^^^^^^^^^^^^^^^^^
  File "/home/airflow/.local/lib/python3.12/site-packages/pyhive/hive.py", line 269, in __init__
    self._transport.open()
  File "/home/airflow/.local/lib/python3.12/site-packages/thrift_sasl/__init__.py", line 74, in open
    self._trans.open()
  File "/home/airflow/.local/lib/python3.12/site-packages/thrift/transport/TSocket.py", line 153, in open
    raise TTransportException(type=TTransportException.NOT_OPEN, message=msg)
thrift.transport.TTransport.TTransportException: Could not connect to any of [('127.0.0.1', 10000), ('::1', 10000, 0, 0)]
[2024-11-04T09:19:12.509+0000] {taskinstance.py:1206} INFO - Marking task as FAILED. dag_id=Loan_Request_Report, task_id=Extract, run_id=manual__2024-11-04T09:17:37.069884+00:00, execution_date=20241104T091737, start_date=20241104T091850, end_date=20241104T091912
[2024-11-04T09:19:13.282+0000] {standard_task_runner.py:110} ERROR - Failed to execute job 24 for task Extract (Could not connect to any of [('127.0.0.1', 10000), ('::1', 10000, 0, 0)]; 223)
[2024-11-04T09:19:13.407+0000] {local_task_job_runner.py:243} INFO - Task exited with return code 1
[2024-11-04T09:19:14.942+0000] {taskinstance.py:3503} INFO - 0 downstream tasks scheduled from follow-on schedule check
[2024-11-04T09:19:15.377+0000] {local_task_job_runner.py:222} INFO - ::endgroup::
