[2024-11-07T19:20:02.190+0000] {local_task_job_runner.py:120} INFO - ::group::Pre task execution logs
[2024-11-07T19:20:02.332+0000] {taskinstance.py:2076} INFO - Dependencies all met for dep_context=non-requeueable deps ti=<TaskInstance: Loan_Request_Report.Extract __airflow_temporary_run_2024-11-07T19:19:55.353602+00:00__ [queued]>
[2024-11-07T19:20:02.357+0000] {taskinstance.py:2076} INFO - Dependencies all met for dep_context=requeueable deps ti=<TaskInstance: Loan_Request_Report.Extract __airflow_temporary_run_2024-11-07T19:19:55.353602+00:00__ [queued]>
[2024-11-07T19:20:02.358+0000] {taskinstance.py:2306} INFO - Starting attempt 1 of 1
[2024-11-07T19:20:02.416+0000] {taskinstance.py:2330} INFO - Executing <Task(PythonOperator): Extract> on 2024-06-11 00:00:00+00:00
[2024-11-07T19:20:02.433+0000] {warnings.py:112} WARNING - /home/***/.local/lib/python3.12/site-packages/***/task/task_runner/standard_task_runner.py:62: DeprecationWarning: This process (pid=156) is multi-threaded, use of fork() may lead to deadlocks in the child.
  pid = os.fork()

[2024-11-07T19:20:02.438+0000] {standard_task_runner.py:64} INFO - Started process 165 to run task
[2024-11-07T19:20:02.441+0000] {standard_task_runner.py:90} INFO - Running: ['***', 'tasks', 'run', 'Loan_Request_Report', 'Extract', '__***_temporary_run_2024-11-07T19:19:55.353602+00:00__', '--job-id', '182', '--raw', '--subdir', 'DAGS_FOLDER/dagLoanRequest.py', '--cfg-path', '/tmp/tmp0hg7o9uc']
[2024-11-07T19:20:02.444+0000] {standard_task_runner.py:91} INFO - Job 182: Subtask Extract
[2024-11-07T19:20:02.752+0000] {task_command.py:426} INFO - Running <TaskInstance: Loan_Request_Report.Extract __airflow_temporary_run_2024-11-07T19:19:55.353602+00:00__ [running]> on host 2bac939b7bc7
[2024-11-07T19:20:03.287+0000] {taskinstance.py:2648} INFO - Exporting env vars: AIRFLOW_CTX_DAG_OWNER='***' AIRFLOW_CTX_DAG_ID='Loan_Request_Report' AIRFLOW_CTX_TASK_ID='Extract' AIRFLOW_CTX_EXECUTION_DATE='2024-06-11T00:00:00+00:00' AIRFLOW_CTX_TRY_NUMBER='1' AIRFLOW_CTX_DAG_RUN_ID='__***_temporary_run_2024-11-07T19:19:55.353602+00:00__'
[2024-11-07T19:20:03.294+0000] {taskinstance.py:430} INFO - ::endgroup::
[2024-11-07T19:20:03.303+0000] {taskinstance.py:441} INFO - ::group::Post task execution logs
[2024-11-07T19:20:03.304+0000] {taskinstance.py:2905} ERROR - Task failed with exception
Traceback (most recent call last):
  File "/home/airflow/.local/lib/python3.12/site-packages/airflow/models/taskinstance.py", line 465, in _execute_task
    result = _execute_callable(context=context, **execute_callable_kwargs)
             ^^^^^^^^^^^^^^^^^^^^^^^^^^^^^^^^^^^^^^^^^^^^^^^^^^^^^^^^^^^^^
  File "/home/airflow/.local/lib/python3.12/site-packages/airflow/models/taskinstance.py", line 432, in _execute_callable
    return execute_callable(context=context, **execute_callable_kwargs)
           ^^^^^^^^^^^^^^^^^^^^^^^^^^^^^^^^^^^^^^^^^^^^^^^^^^^^^^^^^^^^
  File "/home/airflow/.local/lib/python3.12/site-packages/airflow/models/baseoperator.py", line 401, in wrapper
    return func(self, *args, **kwargs)
           ^^^^^^^^^^^^^^^^^^^^^^^^^^^
  File "/home/airflow/.local/lib/python3.12/site-packages/airflow/operators/python.py", line 235, in execute
    return_value = self.execute_callable()
                   ^^^^^^^^^^^^^^^^^^^^^^^
  File "/home/airflow/.local/lib/python3.12/site-packages/airflow/operators/python.py", line 252, in execute_callable
    return self.python_callable(*self.op_args, **self.op_kwargs)
           ^^^^^^^^^^^^^^^^^^^^^^^^^^^^^^^^^^^^^^^^^^^^^^^^^^^^^
  File "/opt/airflow/dags/dagLoanRequest.py", line 31, in extract_task
    merged_df, original_df = extract_data_from_hive(kwargs['required_date'])
                             ^^^^^^^^^^^^^^^^^^^^^^^^^^^^^^^^^^^^^^^^^^^^^^^
  File "/opt/airflow/dags/etlProcess.py", line 84, in extract_data_from_hive
    conn = hive.Connection(host="hive-server", port=10000, database='m2t')
           ^^^^^^^^^^^^^^^^^^^^^^^^^^^^^^^^^^^^^^^^^^^^^^^^^^^^^^^^^^^^^^^
  File "/home/airflow/.local/lib/python3.12/site-packages/pyhive/hive.py", line 242, in __init__
    import thrift_sasl
ModuleNotFoundError: No module named 'thrift_sasl'
[2024-11-07T19:20:03.387+0000] {taskinstance.py:1206} INFO - Marking task as FAILED. dag_id=Loan_Request_Report, task_id=Extract, run_id=__***_temporary_run_2024-11-07T19:19:55.353602+00:00__, execution_date=20240611T000000, start_date=20241107T192002, end_date=20241107T192003
[2024-11-07T19:20:03.480+0000] {standard_task_runner.py:110} ERROR - Failed to execute job 182 for task Extract (No module named 'thrift_sasl'; 165)
[2024-11-07T19:20:03.576+0000] {local_task_job_runner.py:243} INFO - Task exited with return code 1
[2024-11-07T19:20:03.889+0000] {taskinstance.py:3503} INFO - 0 downstream tasks scheduled from follow-on schedule check
[2024-11-07T19:20:04.052+0000] {local_task_job_runner.py:222} INFO - ::endgroup::
